[2024-07-16T22:18:18.863+0000] {local_task_job_runner.py:120} INFO - ::group::Pre task execution logs
[2024-07-16T22:18:18.900+0000] {taskinstance.py:2076} INFO - Dependencies all met for dep_context=non-requeueable deps ti=<TaskInstance: parse_data_dag.parse_data manual__2024-07-16T22:09:41.444017+00:00 [queued]>
[2024-07-16T22:18:18.910+0000] {taskinstance.py:2076} INFO - Dependencies all met for dep_context=requeueable deps ti=<TaskInstance: parse_data_dag.parse_data manual__2024-07-16T22:09:41.444017+00:00 [queued]>
[2024-07-16T22:18:18.912+0000] {taskinstance.py:2306} INFO - Starting attempt 2 of 2
[2024-07-16T22:18:18.933+0000] {taskinstance.py:2330} INFO - Executing <Task(PythonOperator): parse_data> on 2024-07-16 22:09:41.444017+00:00
[2024-07-16T22:18:18.946+0000] {warnings.py:112} WARNING - /home/***/.local/lib/python3.12/site-packages/***/task/task_runner/standard_task_runner.py:62: DeprecationWarning: This process (pid=288) is multi-threaded, use of fork() may lead to deadlocks in the child.
  pid = os.fork()

[2024-07-16T22:18:18.948+0000] {standard_task_runner.py:64} INFO - Started process 291 to run task
[2024-07-16T22:18:18.947+0000] {standard_task_runner.py:90} INFO - Running: ['***', 'tasks', 'run', 'parse_data_dag', 'parse_data', 'manual__2024-07-16T22:09:41.444017+00:00', '--job-id', '14', '--raw', '--subdir', 'DAGS_FOLDER/parsing_dag.py', '--cfg-path', '/tmp/tmptyn7ga0s']
[2024-07-16T22:18:18.950+0000] {standard_task_runner.py:91} INFO - Job 14: Subtask parse_data
[2024-07-16T22:18:19.011+0000] {task_command.py:426} INFO - Running <TaskInstance: parse_data_dag.parse_data manual__2024-07-16T22:09:41.444017+00:00 [running]> on host 1254a1bc6f0b
[2024-07-16T22:18:19.104+0000] {taskinstance.py:2648} INFO - Exporting env vars: AIRFLOW_CTX_DAG_OWNER='***' AIRFLOW_CTX_DAG_ID='parse_data_dag' AIRFLOW_CTX_TASK_ID='parse_data' AIRFLOW_CTX_EXECUTION_DATE='2024-07-16T22:09:41.444017+00:00' AIRFLOW_CTX_TRY_NUMBER='2' AIRFLOW_CTX_DAG_RUN_ID='manual__2024-07-16T22:09:41.444017+00:00'
[2024-07-16T22:18:19.106+0000] {taskinstance.py:430} INFO - ::endgroup::
[2024-07-16T22:18:19.173+0000] {taskinstance.py:441} INFO - ::group::Post task execution logs
[2024-07-16T22:18:19.175+0000] {taskinstance.py:2905} ERROR - Task failed with exception
Traceback (most recent call last):
  File "/home/airflow/.local/lib/python3.12/site-packages/airflow/models/taskinstance.py", line 465, in _execute_task
    result = _execute_callable(context=context, **execute_callable_kwargs)
             ^^^^^^^^^^^^^^^^^^^^^^^^^^^^^^^^^^^^^^^^^^^^^^^^^^^^^^^^^^^^^
  File "/home/airflow/.local/lib/python3.12/site-packages/airflow/models/taskinstance.py", line 432, in _execute_callable
    return execute_callable(context=context, **execute_callable_kwargs)
           ^^^^^^^^^^^^^^^^^^^^^^^^^^^^^^^^^^^^^^^^^^^^^^^^^^^^^^^^^^^^
  File "/home/airflow/.local/lib/python3.12/site-packages/airflow/models/baseoperator.py", line 401, in wrapper
    return func(self, *args, **kwargs)
           ^^^^^^^^^^^^^^^^^^^^^^^^^^^
  File "/home/airflow/.local/lib/python3.12/site-packages/airflow/operators/python.py", line 235, in execute
    return_value = self.execute_callable()
                   ^^^^^^^^^^^^^^^^^^^^^^^
  File "/home/airflow/.local/lib/python3.12/site-packages/airflow/operators/python.py", line 252, in execute_callable
    return self.python_callable(*self.op_args, **self.op_kwargs)
           ^^^^^^^^^^^^^^^^^^^^^^^^^^^^^^^^^^^^^^^^^^^^^^^^^^^^^
  File "/opt/airflow/dags/parsing_dag.py", line 83, in parse_data
    driver = webdriver.Chrome()
             ^^^^^^^^^^^^^^^^^^
  File "/home/airflow/.local/lib/python3.12/site-packages/selenium/webdriver/chrome/webdriver.py", line 45, in __init__
    super().__init__(
  File "/home/airflow/.local/lib/python3.12/site-packages/selenium/webdriver/chromium/webdriver.py", line 55, in __init__
    self.service.start()
  File "/home/airflow/.local/lib/python3.12/site-packages/selenium/webdriver/common/service.py", line 102, in start
    self.assert_process_still_running()
  File "/home/airflow/.local/lib/python3.12/site-packages/selenium/webdriver/common/service.py", line 115, in assert_process_still_running
    raise WebDriverException(f"Service {self._path} unexpectedly exited. Status code was: {return_code}")
selenium.common.exceptions.WebDriverException: Message: Service /home/airflow/.cache/selenium/chromedriver/linux64/126.0.6478.127/chromedriver unexpectedly exited. Status code was: 127

[2024-07-16T22:18:19.194+0000] {taskinstance.py:1206} INFO - Marking task as FAILED. dag_id=parse_data_dag, task_id=parse_data, run_id=manual__2024-07-16T22:09:41.444017+00:00, execution_date=20240716T220941, start_date=20240716T221818, end_date=20240716T221819
[2024-07-16T22:18:19.211+0000] {standard_task_runner.py:110} ERROR - Failed to execute job 14 for task parse_data (Message: Service /home/airflow/.cache/selenium/chromedriver/linux64/126.0.6478.127/chromedriver unexpectedly exited. Status code was: 127
; 291)
[2024-07-16T22:18:19.244+0000] {local_task_job_runner.py:243} INFO - Task exited with return code 1
[2024-07-16T22:18:19.262+0000] {taskinstance.py:3503} INFO - 0 downstream tasks scheduled from follow-on schedule check
[2024-07-16T22:18:19.264+0000] {local_task_job_runner.py:222} INFO - ::endgroup::
