[2024-07-16T22:42:27.735+0000] {local_task_job_runner.py:120} INFO - ::group::Pre task execution logs
[2024-07-16T22:42:28.173+0000] {taskinstance.py:2076} INFO - Dependencies all met for dep_context=non-requeueable deps ti=<TaskInstance: parse_data_dag.parse_data manual__2024-07-16T22:42:09.398913+00:00 [queued]>
[2024-07-16T22:42:28.181+0000] {taskinstance.py:2076} INFO - Dependencies all met for dep_context=requeueable deps ti=<TaskInstance: parse_data_dag.parse_data manual__2024-07-16T22:42:09.398913+00:00 [queued]>
[2024-07-16T22:42:28.220+0000] {taskinstance.py:2306} INFO - Starting attempt 1 of 2
[2024-07-16T22:42:28.416+0000] {taskinstance.py:2330} INFO - Executing <Task(PythonOperator): parse_data> on 2024-07-16 22:42:09.398913+00:00
[2024-07-16T22:42:28.446+0000] {warnings.py:112} WARNING - /home/***/.local/lib/python3.12/site-packages/***/task/task_runner/standard_task_runner.py:62: DeprecationWarning: This process (pid=103) is multi-threaded, use of fork() may lead to deadlocks in the child.
  pid = os.fork()

[2024-07-16T22:42:28.449+0000] {standard_task_runner.py:64} INFO - Started process 113 to run task
[2024-07-16T22:42:28.481+0000] {standard_task_runner.py:90} INFO - Running: ['***', 'tasks', 'run', 'parse_data_dag', 'parse_data', 'manual__2024-07-16T22:42:09.398913+00:00', '--job-id', '21', '--raw', '--subdir', 'DAGS_FOLDER/parsing_dag.py', '--cfg-path', '/tmp/tmpjny4t9ly']
[2024-07-16T22:42:28.552+0000] {standard_task_runner.py:91} INFO - Job 21: Subtask parse_data
[2024-07-16T22:42:29.051+0000] {task_command.py:426} INFO - Running <TaskInstance: parse_data_dag.parse_data manual__2024-07-16T22:42:09.398913+00:00 [running]> on host 1254a1bc6f0b
[2024-07-16T22:42:29.211+0000] {taskinstance.py:2648} INFO - Exporting env vars: AIRFLOW_CTX_DAG_OWNER='***' AIRFLOW_CTX_DAG_ID='parse_data_dag' AIRFLOW_CTX_TASK_ID='parse_data' AIRFLOW_CTX_EXECUTION_DATE='2024-07-16T22:42:09.398913+00:00' AIRFLOW_CTX_TRY_NUMBER='1' AIRFLOW_CTX_DAG_RUN_ID='manual__2024-07-16T22:42:09.398913+00:00'
[2024-07-16T22:42:29.215+0000] {taskinstance.py:430} INFO - ::endgroup::
[2024-07-16T22:42:29.217+0000] {taskinstance.py:441} INFO - ::group::Post task execution logs
[2024-07-16T22:42:29.218+0000] {taskinstance.py:2905} ERROR - Task failed with exception
Traceback (most recent call last):
  File "/home/airflow/.local/lib/python3.12/site-packages/airflow/models/taskinstance.py", line 465, in _execute_task
    result = _execute_callable(context=context, **execute_callable_kwargs)
             ^^^^^^^^^^^^^^^^^^^^^^^^^^^^^^^^^^^^^^^^^^^^^^^^^^^^^^^^^^^^^
  File "/home/airflow/.local/lib/python3.12/site-packages/airflow/models/taskinstance.py", line 432, in _execute_callable
    return execute_callable(context=context, **execute_callable_kwargs)
           ^^^^^^^^^^^^^^^^^^^^^^^^^^^^^^^^^^^^^^^^^^^^^^^^^^^^^^^^^^^^
  File "/home/airflow/.local/lib/python3.12/site-packages/airflow/models/baseoperator.py", line 401, in wrapper
    return func(self, *args, **kwargs)
           ^^^^^^^^^^^^^^^^^^^^^^^^^^^
  File "/home/airflow/.local/lib/python3.12/site-packages/airflow/operators/python.py", line 235, in execute
    return_value = self.execute_callable()
                   ^^^^^^^^^^^^^^^^^^^^^^^
  File "/home/airflow/.local/lib/python3.12/site-packages/airflow/operators/python.py", line 252, in execute_callable
    return self.python_callable(*self.op_args, **self.op_kwargs)
           ^^^^^^^^^^^^^^^^^^^^^^^^^^^^^^^^^^^^^^^^^^^^^^^^^^^^^
  File "/opt/airflow/dags/parsing_dag.py", line 89, in parse_data
    driver = webdriver.Remote(
             ^^^^^^^^^^^^^^^^^
TypeError: WebDriver.__init__() got an unexpected keyword argument 'desired_capabilities'
[2024-07-16T22:42:29.240+0000] {taskinstance.py:1206} INFO - Marking task as UP_FOR_RETRY. dag_id=parse_data_dag, task_id=parse_data, run_id=manual__2024-07-16T22:42:09.398913+00:00, execution_date=20240716T224209, start_date=20240716T224228, end_date=20240716T224229
[2024-07-16T22:42:29.269+0000] {standard_task_runner.py:110} ERROR - Failed to execute job 21 for task parse_data (WebDriver.__init__() got an unexpected keyword argument 'desired_capabilities'; 113)
[2024-07-16T22:42:29.320+0000] {local_task_job_runner.py:243} INFO - Task exited with return code 1
[2024-07-16T22:42:29.347+0000] {taskinstance.py:3503} INFO - 0 downstream tasks scheduled from follow-on schedule check
[2024-07-16T22:42:29.350+0000] {local_task_job_runner.py:222} INFO - ::endgroup::
